<robot name="sassa-short-arm">
<link name="body_sasm">
<visual>
<origin xyz="-2.498001805406602216e-16 6.9388939039072283776e-18 1.8041124150158793782e-16" rpy="-9.7843404150693598069e-29 7.888609052210114691e-29 -1.570796326794896558" />
<geometry>
<mesh filename="package:///handle.stl"/>
</geometry>
<material name="handle_material">
<color rgba="1 0 0 1.0"/>
</material>
</visual>
<collision>
<origin xyz="-2.498001805406602216e-16 6.9388939039072283776e-18 1.8041124150158793782e-16" rpy="-9.7843404150693598069e-29 7.888609052210114691e-29 -1.570796326794896558" />
<geometry>
<mesh filename="package:///handle.stl"/>
</geometry>
</collision>
<visual>
<origin xyz="-0.12800000000000033573 1.0408340855861448079e-17 -1.9428902930940239457e-16" rpy="-1.570796326794896558 7.888609052210114691e-29 -1.570796326794896558" />
<geometry>
<mesh filename="package:///body_panel.stl"/>
</geometry>
<material name="body_panel_material">
<color rgba="1 0 0 1.0"/>
</material>
</visual>
<collision>
<origin xyz="-0.12800000000000033573 1.0408340855861448079e-17 -1.9428902930940239457e-16" rpy="-1.570796326794896558 7.888609052210114691e-29 -1.570796326794896558" />
<geometry>
<mesh filename="package:///body_panel.stl"/>
</geometry>
</collision>
<visual>
<origin xyz="0.12800000000000044675 0.060000000000000004718 5.5511151231257827021e-17" rpy="-1.570796326794896558 7.888609052210114691e-29 -1.570796326794896558" />
<geometry>
<mesh filename="package:///rmdx8v3.stl"/>
</geometry>
<material name="rmdx8v3_material">
<color rgba="0.26274509803921569651 0.28235294117647058432 0.30196078431372547213 1.0"/>
</material>
</visual>
<collision>
<origin xyz="0.12800000000000044675 0.060000000000000004718 5.5511151231257827021e-17" rpy="-1.570796326794896558 7.888609052210114691e-29 -1.570796326794896558" />
<geometry>
<mesh filename="package:///rmdx8v3.stl"/>
</geometry>
</collision>
<visual>
<origin xyz="-0.12800000000000033573 0.060000000000000011657 -1.9428902930940239457e-16" rpy="1.570796326794896558 7.888609052210114691e-29 -1.570796326794896558" />
<geometry>
<mesh filename="package:///rmdx8v3.stl"/>
</geometry>
<material name="rmdx8v3_material">
<color rgba="0.26274509803921569651 0.28235294117647058432 0.30196078431372547213 1.0"/>
</material>
</visual>
<collision>
<origin xyz="-0.12800000000000033573 0.060000000000000011657 -1.9428902930940239457e-16" rpy="1.570796326794896558 7.888609052210114691e-29 -1.570796326794896558" />
<geometry>
<mesh filename="package:///rmdx8v3.stl"/>
</geometry>
</collision>
<visual>
<origin xyz="0 -5.5511151231257827021e-17 0" rpy="1.3877787807814453674e-17 -0 -1.57079632679489678" />
<geometry>
<mesh filename="package:///body.stl"/>
</geometry>
<material name="body_material">
<color rgba="0.2745098039215686514 0.2745098039215686514 0.2745098039215686514 1.0"/>
</material>
</visual>
<collision>
<origin xyz="0 -5.5511151231257827021e-17 0" rpy="1.3877787807814453674e-17 -0 -1.57079632679489678" />
<geometry>
<mesh filename="package:///body.stl"/>
</geometry>
</collision>
<visual>
<origin xyz="0.12800000000000044675 1.0408340855860438892e-17 5.5511151231257827021e-17" rpy="1.570796326794896558 7.888609052210114691e-29 -1.570796326794896558" />
<geometry>
<mesh filename="package:///body_panel.stl"/>
</geometry>
<material name="body_panel_material">
<color rgba="1 0 0 1.0"/>
</material>
</visual>
<collision>
<origin xyz="0.12800000000000044675 1.0408340855860438892e-17 5.5511151231257827021e-17" rpy="1.570796326794896558 7.888609052210114691e-29 -1.570796326794896558" />
<geometry>
<mesh filename="package:///body_panel.stl"/>
</geometry>
</collision>
<visual>
<origin xyz="0.12800000000000044675 -0.059999999999999990841 5.5511151231257827021e-17" rpy="-1.570796326794896558 7.888609052210114691e-29 -1.570796326794896558" />
<geometry>
<mesh filename="package:///rmdx8v3.stl"/>
</geometry>
<material name="rmdx8v3_material">
<color rgba="0.26274509803921569651 0.28235294117647058432 0.30196078431372547213 1.0"/>
</material>
</visual>
<collision>
<origin xyz="0.12800000000000044675 -0.059999999999999990841 5.5511151231257827021e-17" rpy="-1.570796326794896558 7.888609052210114691e-29 -1.570796326794896558" />
<geometry>
<mesh filename="package:///rmdx8v3.stl"/>
</geometry>
</collision>
<visual>
<origin xyz="-0.12800000000000033573 -0.059999999999999983902 -1.9428902930940239457e-16" rpy="1.570796326794896558 7.888609052210114691e-29 -1.570796326794896558" />
<geometry>
<mesh filename="package:///rmdx8v3.stl"/>
</geometry>
<material name="rmdx8v3_material">
<color rgba="0.26274509803921569651 0.28235294117647058432 0.30196078431372547213 1.0"/>
</material>
</visual>
<collision>
<origin xyz="-0.12800000000000033573 -0.059999999999999983902 -1.9428902930940239457e-16" rpy="1.570796326794896558 7.888609052210114691e-29 -1.570796326794896558" />
<geometry>
<mesh filename="package:///rmdx8v3.stl"/>
</geometry>
</collision>
<inertial>
<origin xyz="8.0117084818908636674e-08 0.00072784125177793325932 0.00090471073932864309614" rpy="0 0 0"/>
<mass value="3.4789999999999992042" />
<inertia ixx="0.017504232505954519378" ixy="3.3067996075761274533e-09"  ixz="-5.3359980506052898152e-05" iyy="0.062019253873448768055" iyz="2.6326797291481044089e-05" izz="0.073616792579865503177" />
</inertial>
</link>

<link name="helbow_sasm">
<visual>
<origin xyz="-3.1225022567582527699e-17 -0.016999999999999994282 -0.05999999999999999778" rpy="1.570796326794896558 -6.5617017863841870815e-34 6.5617017838168550278e-34" />
<geometry>
<mesh filename="package:///angle_motor_connect.stl"/>
</geometry>
<material name="angle_motor_connect_material">
<color rgba="1 0 0 1.0"/>
</material>
</visual>
<collision>
<origin xyz="-3.1225022567582527699e-17 -0.016999999999999994282 -0.05999999999999999778" rpy="1.570796326794896558 -6.5617017863841870815e-34 6.5617017838168550278e-34" />
<geometry>
<mesh filename="package:///angle_motor_connect.stl"/>
</geometry>
</collision>
<visual>
<origin xyz="-3.1225022567582527699e-17 -0.016999999999999994282 -0.05999999999999999778" rpy="1.570796326794896558 0.3141592653589793116 -3.141592653589793116" />
<geometry>
<mesh filename="package:///rmdx8v3.stl"/>
</geometry>
<material name="rmdx8v3_material">
<color rgba="0.26274509803921569651 0.28235294117647058432 0.30196078431372547213 1.0"/>
</material>
</visual>
<collision>
<origin xyz="-3.1225022567582527699e-17 -0.016999999999999994282 -0.05999999999999999778" rpy="1.570796326794896558 0.3141592653589793116 -3.141592653589793116" />
<geometry>
<mesh filename="package:///rmdx8v3.stl"/>
</geometry>
</collision>
<inertial>
<origin xyz="5.9444804833177515764e-05 -0.0057855661598585949104 -0.054844450125644705896" rpy="0 0 0"/>
<mass value="0.76499999999999979128" />
<inertia ixx="0.00070529619085715170197" ixy="8.1991517066849942041e-07"  ixz="-1.1586194990785329943e-06" iyy="0.0010092480556627560044" iyz="9.9300977410698168741e-06" izz="0.00061029448812635373085" />
</inertial>
</link>

<link name="upperleg_sasm">
<visual>
<origin xyz="7.6290213507511077293e-18 0 -0.079250000000000014877" rpy="1.5707963267948970021 2.9044849690249756194e-16 1.570796326794896558" />
<geometry>
<mesh filename="package:///61804-2rs.stl"/>
</geometry>
<material name="61804-2rs_material">
<color rgba="0.61568627450980395466 0.81176470588235294379 0.92941176470588238168 1.0"/>
</material>
</visual>
<collision>
<origin xyz="7.6290213507511077293e-18 0 -0.079250000000000014877" rpy="1.5707963267948970021 2.9044849690249756194e-16 1.570796326794896558" />
<geometry>
<mesh filename="package:///61804-2rs.stl"/>
</geometry>
</collision>
<visual>
<origin xyz="1.753469930634033528e-16 0 -0.053500000000000075273" rpy="3.141592653589793116 1.0047893711214148772e-16 1.6578076876195083607e-29" />
<geometry>
<mesh filename="package:///upperleg_cover.stl"/>
</geometry>
<material name="upperleg_cover_material">
<color rgba="1 0 0 1.0"/>
</material>
</visual>
<collision>
<origin xyz="1.753469930634033528e-16 0 -0.053500000000000075273" rpy="3.141592653589793116 1.0047893711214148772e-16 1.6578076876195083607e-29" />
<geometry>
<mesh filename="package:///upperleg_cover.stl"/>
</geometry>
</collision>
<visual>
<origin xyz="-3.0814879110195773649e-33 0 -0.023000000000000020428" rpy="1.570796326794896558 -0 0" />
<geometry>
<mesh filename="package:///inline_connect.stl"/>
</geometry>
<material name="inline_connect_material">
<color rgba="1 0 0 1.0"/>
</material>
</visual>
<collision>
<origin xyz="-3.0814879110195773649e-33 0 -0.023000000000000020428" rpy="1.570796326794896558 -0 0" />
<geometry>
<mesh filename="package:///inline_connect.stl"/>
</geometry>
</collision>
<visual>
<origin xyz="8.3984370386311552134e-18 0 -0.056000000000000021982" rpy="-3.141592653589793116 6.8403891977347234462e-17 1.570796326794896558" />
<geometry>
<mesh filename="package:///motor_pulley.stl"/>
</geometry>
<material name="motor_pulley_material">
<color rgba="1 0 0 1.0"/>
</material>
</visual>
<collision>
<origin xyz="8.3984370386311552134e-18 0 -0.056000000000000021982" rpy="-3.141592653589793116 6.8403891977347234462e-17 1.570796326794896558" />
<geometry>
<mesh filename="package:///motor_pulley.stl"/>
</geometry>
</collision>
<visual>
<origin xyz="1.3877787807814456755e-17 0 -0.02300000000000000655" rpy="-3.141592653589793116 6.8403891977347234462e-17 1.570796326794896558" />
<geometry>
<mesh filename="package:///rmdx8v3.stl"/>
</geometry>
<material name="rmdx8v3_material">
<color rgba="0.26274509803921569651 0.28235294117647058432 0.30196078431372547213 1.0"/>
</material>
</visual>
<collision>
<origin xyz="1.3877787807814456755e-17 0 -0.02300000000000000655" rpy="-3.141592653589793116 6.8403891977347234462e-17 1.570796326794896558" />
<geometry>
<mesh filename="package:///rmdx8v3.stl"/>
</geometry>
</collision>
<visual>
<origin xyz="3.6569114985258803736e-17 0 -0.053500000000000019762" rpy="-3.1415926535897926719 3.4480744915607654605e-16 1.6566079009641247914e-29" />
<geometry>
<mesh filename="package:///upperleg_main.stl"/>
</geometry>
<material name="upperleg_main_material">
<color rgba="1 0 0 1.0"/>
</material>
</visual>
<collision>
<origin xyz="3.6569114985258803736e-17 0 -0.053500000000000019762" rpy="-3.1415926535897926719 3.4480744915607654605e-16 1.6566079009641247914e-29" />
<geometry>
<mesh filename="package:///upperleg_main.stl"/>
</geometry>
</collision>
<inertial>
<origin xyz="0.015354642915121939975 -1.5253104185110740829e-07 -0.040813023259634394202" rpy="0 0 0"/>
<mass value="0.89199999999999979305" />
<inertia ixx="0.00078712622936624688716" ixy="2.0249252559937008518e-08"  ixz="0.00040224017032634937652" iyy="0.0026932453248710609695" iyz="-3.6830453734419931036e-09" izz="0.002828998648874843716" />
</inertial>
</link>

<link name="lowerleg_sasm">
<visual>
<origin xyz="2.7755575615628913511e-17 0 -2.7755575615628913511e-17" rpy="2.9330896303248668082e-32 5.2919806624416397802e-31 -8.9902534028177188512e-32" />
<geometry>
<mesh filename="package:///lower_leg.stl"/>
</geometry>
<material name="lower_leg_material">
<color rgba="1 0 0 1.0"/>
</material>
</visual>
<collision>
<origin xyz="2.7755575615628913511e-17 0 -2.7755575615628913511e-17" rpy="2.9330896303248668082e-32 5.2919806624416397802e-31 -8.9902534028177188512e-32" />
<geometry>
<mesh filename="package:///lower_leg.stl"/>
</geometry>
</collision>
<visual>
<origin xyz="2.7755575615628913511e-17 0 -0.0060000000000000330846" rpy="-1.5707963267948992225 1.5694156464006572129e-15 1.0330794565568739415e-30" />
<geometry>
<mesh filename="package:///61804-2rs.stl"/>
</geometry>
<material name="61804-2rs_material">
<color rgba="0.61568627450980395466 0.81176470588235294379 0.92941176470588238168 1.0"/>
</material>
</visual>
<collision>
<origin xyz="2.7755575615628913511e-17 0 -0.0060000000000000330846" rpy="-1.5707963267948992225 1.5694156464006572129e-15 1.0330794565568739415e-30" />
<geometry>
<mesh filename="package:///61804-2rs.stl"/>
</geometry>
</collision>
<visual>
<origin xyz="2.7755575615628913511e-17 0 0.0060000000000000608402" rpy="1.5707963267949018871 3.2630587779497501504e-15 3.4947918559641619179e-31" />
<geometry>
<mesh filename="package:///61804-2rs.stl"/>
</geometry>
<material name="61804-2rs_material">
<color rgba="0.61568627450980395466 0.81176470588235294379 0.92941176470588238168 1.0"/>
</material>
</visual>
<collision>
<origin xyz="2.7755575615628913511e-17 0 0.0060000000000000608402" rpy="1.5707963267949018871 3.2630587779497501504e-15 3.4947918559641619179e-31" />
<geometry>
<mesh filename="package:///61804-2rs.stl"/>
</geometry>
</collision>
<visual>
<origin xyz="-1.415534356397074589e-15 0 3.0531133177191804862e-16" rpy="-2.5827259566927633692e-15 1.5694156464006621433e-15 1.0330794565568739415e-30" />
<geometry>
<mesh filename="package:///foot_ball.stl"/>
</geometry>
<material name="foot_ball_material">
<color rgba="0.26274509803921569651 0.28235294117647058432 0.30196078431372547213 1.0"/>
</material>
</visual>
<collision>
<origin xyz="-1.415534356397074589e-15 0 3.0531133177191804862e-16" rpy="-2.5827259566927633692e-15 1.5694156464006621433e-15 1.0330794565568739415e-30" />
<geometry>
<mesh filename="package:///foot_ball.stl"/>
</geometry>
</collision>
<inertial>
<origin xyz="0.092866734428134853352 3.4061659239153585728e-09 -1.3731468408362567947e-09" rpy="0 0 0"/>
<mass value="0.13200000000000000622" />
<inertia ixx="1.7231392269124699032e-05" ixy="2.777660556243905499e-11"  ixz="-1.125407529616378851e-11" iyy="0.00097781315953662188006" iyz="-2.3904249468381147268e-11" izz="0.00098262259218384780113" />
</inertial>
</link>

<link name="FL_foot">
<inertial>
<origin xyz="0 0 0" rpy="0 0 0" />
<mass value="1e-9" />
<inertia ixx="0" ixy="0" ixz="0" iyy="0" iyz="0" izz="0" />
</inertial>
</link>
<joint name="FL_foot_frame" type="fixed">
<origin xyz="0.21732050807564642914 -2.7339241981394479808e-14 -2.7755575615628913511e-17" rpy="-1.5707963267948950037 2.5827259566927519308e-15 1.570796326794896558" />
<parent link="lowerleg_sasm" />
<child link="FL_foot" />
<axis xyz="0 0 0"/>
</joint>

<joint name="FL2" type="revolute">
<origin xyz="0.21300000000000002265 6.4392935428259079345e-15 -0.068500000000000116351" rpy="5.3799142389700426073e-16 -2.219643924176522297e-15 -1.160061430643682592e-15" />
<parent link="upperleg_sasm" />
<child link="lowerleg_sasm" />
<axis xyz="0 0 1"/>
<limit effort="9" velocity="20" lower="-2.356194490192344837" upper="2.356194490192344837"/>
<joint_properties friction="0.0"/>
</joint>

<joint name="FL1" type="revolute">
<origin xyz="-2.1926730353241371394e-17 0.016000000000000007272 -0.05999999999999999778" rpy="-1.570796326794896558 -1.4025207337730963138e-27 -3.141592653589793116" />
<parent link="helbow_sasm" />
<child link="upperleg_sasm" />
<axis xyz="0 0 1"/>
<limit effort="9" velocity="20" lower="-1.570796326794896558" upper="1.570796326794896558"/>
<joint_properties friction="0.0"/>
</joint>

<joint name="FL0" type="revolute">
<origin xyz="0.16100000000000047606 0.060000000000000004718 6.00732341963438899e-17" rpy="-3.1278740296522731543e-30 -1.570796326794896336 0" />
<parent link="body_sasm" />
<child link="helbow_sasm" />
<axis xyz="0 0 1"/>
<limit effort="9" velocity="20" lower="-0.785398163397448279" upper="0.785398163397448279"/>
<joint_properties friction="0.0"/>
</joint>

<link name="helbow_sasm_2">
<visual>
<origin xyz="-3.1225022567582533862e-17 -0.016999999999999994282 -0.05999999999999999778" rpy="1.570796326794896558 -3.6953570529203814193e-39 1.5407439555083695941e-33" />
<geometry>
<mesh filename="package:///angle_motor_connect.stl"/>
</geometry>
<material name="angle_motor_connect_material">
<color rgba="1 0 0 1.0"/>
</material>
</visual>
<collision>
<origin xyz="-3.1225022567582533862e-17 -0.016999999999999994282 -0.05999999999999999778" rpy="1.570796326794896558 -3.6953570529203814193e-39 1.5407439555083695941e-33" />
<geometry>
<mesh filename="package:///angle_motor_connect.stl"/>
</geometry>
</collision>
<visual>
<origin xyz="-3.0357660829594130315e-17 -0.016999999999999994282 -0.05999999999999999778" rpy="1.57079632679489678 0.31415926535897936711 3.141592653589793116" />
<geometry>
<mesh filename="package:///rmdx8v3.stl"/>
</geometry>
<material name="rmdx8v3_material">
<color rgba="0.26274509803921569651 0.28235294117647058432 0.30196078431372547213 1.0"/>
</material>
</visual>
<collision>
<origin xyz="-3.0357660829594130315e-17 -0.016999999999999994282 -0.05999999999999999778" rpy="1.57079632679489678 0.31415926535897936711 3.141592653589793116" />
<geometry>
<mesh filename="package:///rmdx8v3.stl"/>
</geometry>
</collision>
<inertial>
<origin xyz="5.9444804833174859468e-05 -0.0057855661598585975125 -0.054844450125644705896" rpy="0 0 0"/>
<mass value="0.76499999999999979128" />
<inertia ixx="0.00070529619085715148513" ixy="8.1991517066812736119e-07"  ixz="-1.1586194990783294947e-06" iyy="0.0010092480556627560044" iyz="9.9300977410696186684e-06" izz="0.00061029448812635329717" />
</inertial>
</link>

<link name="upperleg_sasm_2">
<visual>
<origin xyz="0 -2.7755575615628913511e-17 0.023000000000000020428" rpy="-1.570796326794896558 2.5291602972405318469e-32 -2.7150157746293330749e-44" />
<geometry>
<mesh filename="package:///inline_connect.stl"/>
</geometry>
<material name="inline_connect_material">
<color rgba="1 0 0 1.0"/>
</material>
</visual>
<collision>
<origin xyz="0 -2.7755575615628913511e-17 0.023000000000000020428" rpy="-1.570796326794896558 2.5291602972405318469e-32 -2.7150157746293330749e-44" />
<geometry>
<mesh filename="package:///inline_connect.stl"/>
</geometry>
</collision>
<visual>
<origin xyz="-1.7205465538984564751e-16 -1.3877787807814456755e-16 0.079250000000000278555" rpy="-1.570796326794896336 -9.714451465469948398e-17 -1.570796326794896336" />
<geometry>
<mesh filename="package:///61804-2rs.stl"/>
</geometry>
<material name="61804-2rs_material">
<color rgba="0.61568627450980395466 0.81176470588235294379 0.92941176470588238168 1.0"/>
</material>
</visual>
<collision>
<origin xyz="-1.7205465538984564751e-16 -1.3877787807814456755e-16 0.079250000000000278555" rpy="-1.570796326794896336 -9.714451465469948398e-17 -1.570796326794896336" />
<geometry>
<mesh filename="package:///61804-2rs.stl"/>
</geometry>
</collision>
<visual>
<origin xyz="-1.7731282339771384989e-16 -1.3877787807814456755e-16 0.056000000000000091371" rpy="5.4123372450474941675e-16 -2.5847379792053932669e-16 -1.570796326794896336" />
<geometry>
<mesh filename="package:///motor_pulley.stl"/>
</geometry>
<material name="motor_pulley_material">
<color rgba="1 0 0 1.0"/>
</material>
</visual>
<collision>
<origin xyz="-1.7731282339771384989e-16 -1.3877787807814456755e-16 0.056000000000000091371" rpy="5.4123372450474941675e-16 -2.5847379792053932669e-16 -1.570796326794896336" />
<geometry>
<mesh filename="package:///motor_pulley.stl"/>
</geometry>
</collision>
<visual>
<origin xyz="8.6633917922066816174e-15 -3.6082248300317587564e-16 0.053500000000000505485" rpy="1.9949319973733131209e-16 9.2981178312356663045e-16 -2.775557561563065147e-17" />
<geometry>
<mesh filename="package:///upperleg_cover.stl"/>
</geometry>
<material name="upperleg_cover_material">
<color rgba="1 0 0 1.0"/>
</material>
</visual>
<collision>
<origin xyz="8.6633917922066816174e-15 -3.6082248300317587564e-16 0.053500000000000505485" rpy="1.9949319973733131209e-16 9.2981178312356663045e-16 -2.775557561563065147e-17" />
<geometry>
<mesh filename="package:///upperleg_cover.stl"/>
</geometry>
</collision>
<visual>
<origin xyz="8.2386461239203363498e-16 -3.8857805861880478915e-16 0.053500000000000005884" rpy="5.0007687304695769841e-16 2.8852669743158039726e-16 -2.7755575615620568841e-17" />
<geometry>
<mesh filename="package:///upperleg_main.stl"/>
</geometry>
<material name="upperleg_main_material">
<color rgba="1 0 0 1.0"/>
</material>
</visual>
<collision>
<origin xyz="8.2386461239203363498e-16 -3.8857805861880478915e-16 0.053500000000000005884" rpy="5.0007687304695769841e-16 2.8852669743158039726e-16 -2.7755575615620568841e-17" />
<geometry>
<mesh filename="package:///upperleg_main.stl"/>
</geometry>
</collision>
<visual>
<origin xyz="-1.8735013540549358847e-16 -1.3877787807814456755e-16 0.02300000000000000655" rpy="6.6613381477508633147e-16 -1.2143064331837457376e-16 -1.570796326794896558" />
<geometry>
<mesh filename="package:///rmdx8v3.stl"/>
</geometry>
<material name="rmdx8v3_material">
<color rgba="0.26274509803921569651 0.28235294117647058432 0.30196078431372547213 1.0"/>
</material>
</visual>
<collision>
<origin xyz="-1.8735013540549358847e-16 -1.3877787807814456755e-16 0.02300000000000000655" rpy="6.6613381477508633147e-16 -1.2143064331837457376e-16 -1.570796326794896558" />
<geometry>
<mesh filename="package:///rmdx8v3.stl"/>
</geometry>
</collision>
<inertial>
<origin xyz="0.015354642915122646007 1.5253104167238726807e-07 0.040813023259634449713" rpy="0 0 0"/>
<mass value="0.89199999999999979305" />
<inertia ixx="0.00078712622936625642814" ixy="-2.0249252556378881187e-08"  ixz="-0.00040224017032637523475" iyy="0.002693245324871220564" iyz="-3.6830453724792541322e-09" izz="0.0028289986488749998411" />
</inertial>
</link>

<link name="lowerleg_sasm_2">
<visual>
<origin xyz="0 -2.7755575615628913511e-17 -0.0059999999999999775735" rpy="-1.57079632679489678 5.781209582702274372e-32 -1.8562439446568260626e-17" />
<geometry>
<mesh filename="package:///61804-2rs.stl"/>
</geometry>
<material name="61804-2rs_material">
<color rgba="0.61568627450980395466 0.81176470588235294379 0.92941176470588238168 1.0"/>
</material>
</visual>
<collision>
<origin xyz="0 -2.7755575615628913511e-17 -0.0059999999999999775735" rpy="-1.57079632679489678 5.781209582702274372e-32 -1.8562439446568260626e-17" />
<geometry>
<mesh filename="package:///61804-2rs.stl"/>
</geometry>
</collision>
<visual>
<origin xyz="-2.2204460492503130808e-16 -2.7755575615628913511e-17 -2.7755575615628913511e-17" rpy="-2.8969882048802926184e-16 -8.8397666051774869371e-32 -4.6846516387535727591e-18" />
<geometry>
<mesh filename="package:///foot_ball.stl"/>
</geometry>
<material name="foot_ball_material">
<color rgba="0.26274509803921569651 0.28235294117647058432 0.30196078431372547213 1.0"/>
</material>
</visual>
<collision>
<origin xyz="-2.2204460492503130808e-16 -2.7755575615628913511e-17 -2.7755575615628913511e-17" rpy="-2.8969882048802926184e-16 -8.8397666051774869371e-32 -4.6846516387535727591e-18" />
<geometry>
<mesh filename="package:///foot_ball.stl"/>
</geometry>
</collision>
<visual>
<origin xyz="0 0 0" rpy="-3.539406725163545736e-32 -0 0" />
<geometry>
<mesh filename="package:///lower_leg.stl"/>
</geometry>
<material name="lower_leg_material">
<color rgba="1 0 0 1.0"/>
</material>
</visual>
<collision>
<origin xyz="0 0 0" rpy="-3.539406725163545736e-32 -0 0" />
<geometry>
<mesh filename="package:///lower_leg.stl"/>
</geometry>
</collision>
<visual>
<origin xyz="0 0 0.0060000000000000053291" rpy="1.5707963267948956698 4.6419140727812833279e-16 -4.6846516387532276325e-18" />
<geometry>
<mesh filename="package:///61804-2rs.stl"/>
</geometry>
<material name="61804-2rs_material">
<color rgba="0.61568627450980395466 0.81176470588235294379 0.92941176470588238168 1.0"/>
</material>
</visual>
<collision>
<origin xyz="0 0 0.0060000000000000053291" rpy="1.5707963267948956698 4.6419140727812833279e-16 -4.6846516387532276325e-18" />
<geometry>
<mesh filename="package:///61804-2rs.stl"/>
</geometry>
</collision>
<inertial>
<origin xyz="0.092866734428134811719 3.4061659146809164599e-09 -1.3731468243038753816e-09" rpy="0 0 0"/>
<mass value="0.13200000000000000622" />
<inertia ixx="1.7231392269124600776e-05" ixy="2.7776605595296717485e-11"  ixz="-1.1254075308383265641e-11" iyy="0.00097781315953662166322" iyz="-2.3904249474057111997e-11" izz="0.00098262259218384736745" />
</inertial>
</link>

<link name="FR_foot">
<inertial>
<origin xyz="0 0 0" rpy="0 0 0" />
<mass value="1e-9" />
<inertia ixx="0" ixy="0" ixz="0" iyy="0" iyz="0" izz="0" />
</inertial>
</link>
<joint name="FR_foot_frame" type="fixed">
<origin xyz="0.21732050807564642914 -2.7311486405778850894e-14 2.7755575615628913511e-17" rpy="-1.57079632679489678 2.8969882048802945905e-16 1.57079632679489678" />
<parent link="lowerleg_sasm_2" />
<child link="FR_foot" />
<axis xyz="0 0 0"/>
</joint>

<joint name="FR2" type="revolute">
<origin xyz="0.21300000000000707256 -6.8001160258290838101e-15 0.068500000000000324518" rpy="9.151465190478033992e-16 8.1952459146742595553e-16 -8.5573819244574777506e-16" />
<parent link="upperleg_sasm_2" />
<child link="lowerleg_sasm_2" />
<axis xyz="0 0 1"/>
<limit effort="9" velocity="20" lower="-2.356194490192344837" upper="2.356194490192344837"/>
<joint_properties friction="0.0"/>
</joint>

<joint name="FR1" type="revolute">
<origin xyz="-4.9101225674844351158e-15 0.015999999999999854616 -0.060000000000000691669" rpy="-1.57079632679489678 -2.4980021557732987213e-16 1.7493215015995355113e-16" />
<parent link="helbow_sasm_2" />
<child link="upperleg_sasm_2" />
<axis xyz="0 0 1"/>
<limit effort="9" velocity="20" lower="-1.570796326794896558" upper="1.570796326794896558"/>
<joint_properties friction="0.0"/>
</joint>

<joint name="FR0" type="revolute">
<origin xyz="0.16100000000000128098 -0.060000000000000025535 3.9822312145179352385e-17" rpy="3.141592653589793116 1.570796326794896558 0" />
<parent link="body_sasm" />
<child link="helbow_sasm_2" />
<axis xyz="0 0 1"/>
<limit effort="9" velocity="20" lower="-0.785398163397448279" upper="0.785398163397448279"/>
<joint_properties friction="0.0"/>
</joint>

<link name="helbow_sasm_3">
<visual>
<origin xyz="-3.1225022567582527699e-17 -0.016999999999999994282 -0.05999999999999999778" rpy="1.570796326794896558 0.3141592653589793116 -3.141592653589793116" />
<geometry>
<mesh filename="package:///rmdx8v3.stl"/>
</geometry>
<material name="rmdx8v3_material">
<color rgba="0.26274509803921569651 0.28235294117647058432 0.30196078431372547213 1.0"/>
</material>
</visual>
<collision>
<origin xyz="-3.1225022567582527699e-17 -0.016999999999999994282 -0.05999999999999999778" rpy="1.570796326794896558 0.3141592653589793116 -3.141592653589793116" />
<geometry>
<mesh filename="package:///rmdx8v3.stl"/>
</geometry>
</collision>
<visual>
<origin xyz="-3.1225022567582527699e-17 -0.016999999999999994282 -0.05999999999999999778" rpy="1.570796326794896558 3.8110772711717211778e-33 -2.8025969286495594657e-45" />
<geometry>
<mesh filename="package:///angle_motor_connect.stl"/>
</geometry>
<material name="angle_motor_connect_material">
<color rgba="1 0 0 1.0"/>
</material>
</visual>
<collision>
<origin xyz="-3.1225022567582527699e-17 -0.016999999999999994282 -0.05999999999999999778" rpy="1.570796326794896558 3.8110772711717211778e-33 -2.8025969286495594657e-45" />
<geometry>
<mesh filename="package:///angle_motor_connect.stl"/>
</geometry>
</collision>
<inertial>
<origin xyz="5.9444804833179331802e-05 -0.0057855661598586018493 -0.054844450125644705896" rpy="0 0 0"/>
<mass value="0.76499999999999979128" />
<inertia ixx="0.00070529619085715256933" ixy="8.1991517066869381447e-07"  ixz="-1.1586194990786757194e-06" iyy="0.0010092480556627555707" iyz="9.9300977410697728283e-06" izz="0.00061029448812635492348" />
</inertial>
</link>

<link name="upperleg_sasm_3">
<visual>
<origin xyz="3.4763482264219987944e-16 -6.6613381477509392425e-16 -0.079249999999999903855" rpy="1.5707963267949121011 -8.7708493677194047434e-31 1.570796326794896558" />
<geometry>
<mesh filename="package:///61804-2rs.stl"/>
</geometry>
<material name="61804-2rs_material">
<color rgba="0.61568627450980395466 0.81176470588235294379 0.92941176470588238168 1.0"/>
</material>
</visual>
<collision>
<origin xyz="3.4763482264219987944e-16 -6.6613381477509392425e-16 -0.079249999999999903855" rpy="1.5707963267949121011 -8.7708493677194047434e-31 1.570796326794896558" />
<geometry>
<mesh filename="package:///61804-2rs.stl"/>
</geometry>
</collision>
<visual>
<origin xyz="3.9443045261050590271e-31 0 -0.023000000000000020428" rpy="1.570796326794896558 1.12266282378325968e-31 -1.5869662741828017458e-31" />
<geometry>
<mesh filename="package:///inline_connect.stl"/>
</geometry>
<material name="inline_connect_material">
<color rgba="1 0 0 1.0"/>
</material>
</visual>
<collision>
<origin xyz="3.9443045261050590271e-31 0 -0.023000000000000020428" rpy="1.570796326794896558 1.12266282378325968e-31 -1.5869662741828017458e-31" />
<geometry>
<mesh filename="package:///inline_connect.stl"/>
</geometry>
</collision>
<visual>
<origin xyz="-1.6516246738967529295e-16 -4.4408920985006261617e-16 -0.053500000000000019762" rpy="-3.1415926535897900074 -4.9960036108130584926e-15 6.4739880123452744713e-15" />
<geometry>
<mesh filename="package:///upperleg_cover.stl"/>
</geometry>
<material name="upperleg_cover_material">
<color rgba="1 0 0 1.0"/>
</material>
</visual>
<collision>
<origin xyz="-1.6516246738967529295e-16 -4.4408920985006261617e-16 -0.053500000000000019762" rpy="-3.1415926535897900074 -4.9960036108130584926e-15 6.4739880123452744713e-15" />
<geometry>
<mesh filename="package:///upperleg_cover.stl"/>
</geometry>
</collision>
<visual>
<origin xyz="9.4506055723547158392e-16 -4.4408920985006261617e-16 -0.053500000000000019762" rpy="-3.1415926535897908956 -4.9960036108130584926e-15 6.4739880123452784156e-15" />
<geometry>
<mesh filename="package:///upperleg_main.stl"/>
</geometry>
<material name="upperleg_main_material">
<color rgba="1 0 0 1.0"/>
</material>
</visual>
<collision>
<origin xyz="9.4506055723547158392e-16 -4.4408920985006261617e-16 -0.053500000000000019762" rpy="-3.1415926535897908956 -4.9960036108130584926e-15 6.4739880123452784156e-15" />
<geometry>
<mesh filename="package:///upperleg_main.stl"/>
</geometry>
</collision>
<visual>
<origin xyz="3.4694469519535698154e-16 -3.3306690738754696213e-16 -0.023000000000000228595" rpy="3.141592653589788231 -2.454806747213854959e-30 1.570796326794896558" />
<geometry>
<mesh filename="package:///rmdx8v3.stl"/>
</geometry>
<material name="rmdx8v3_material">
<color rgba="0.26274509803921569651 0.28235294117647058432 0.30196078431372547213 1.0"/>
</material>
</visual>
<collision>
<origin xyz="3.4694469519535698154e-16 -3.3306690738754696213e-16 -0.023000000000000228595" rpy="3.141592653589788231 -2.454806747213854959e-30 1.570796326794896558" />
<geometry>
<mesh filename="package:///rmdx8v3.stl"/>
</geometry>
</collision>
<visual>
<origin xyz="3.4387796306280250907e-16 -5.273559366969493567e-16 -0.056000000000000021982" rpy="3.141592653589788231 -2.454806747213854959e-30 1.570796326794896558" />
<geometry>
<mesh filename="package:///motor_pulley.stl"/>
</geometry>
<material name="motor_pulley_material">
<color rgba="1 0 0 1.0"/>
</material>
</visual>
<collision>
<origin xyz="3.4387796306280250907e-16 -5.273559366969493567e-16 -0.056000000000000021982" rpy="3.141592653589788231 -2.454806747213854959e-30 1.570796326794896558" />
<geometry>
<mesh filename="package:///motor_pulley.stl"/>
</geometry>
</collision>
<inertial>
<origin xyz="0.015354642915122321614 -1.5253104216442516018e-07 -0.040813023259634401141" rpy="0 0 0"/>
<mass value="0.89199999999999979305" />
<inertia ixx="0.00078712622936623268411" ixy="2.0249252574927046538e-08"  ixz="0.0004022401703263363661" iyy="0.0026932453248710522958" iyz="-3.6830453595166209038e-09" izz="0.0028289986488748337413" />
</inertial>
</link>

<link name="lowerleg_sasm_3">
<visual>
<origin xyz="0 0 0" rpy="4.9814313959820394058e-33 -1.354866199554786051e-30 -1.1832913578319268873e-30" />
<geometry>
<mesh filename="package:///lower_leg.stl"/>
</geometry>
<material name="lower_leg_material">
<color rgba="1 0 0 1.0"/>
</material>
</visual>
<collision>
<origin xyz="0 0 0" rpy="4.9814313959820394058e-33 -1.354866199554786051e-30 -1.1832913578319268873e-30" />
<geometry>
<mesh filename="package:///lower_leg.stl"/>
</geometry>
</collision>
<visual>
<origin xyz="0 -2.7755575615628913511e-17 -0.0060000000000000053291" rpy="-1.57079632679489678 -2.0665654347996242627e-30 3.155443620841420423e-30" />
<geometry>
<mesh filename="package:///61804-2rs.stl"/>
</geometry>
<material name="61804-2rs_material">
<color rgba="0.61568627450980395466 0.81176470588235294379 0.92941176470588238168 1.0"/>
</material>
</visual>
<collision>
<origin xyz="0 -2.7755575615628913511e-17 -0.0060000000000000053291" rpy="-1.57079632679489678 -2.0665654347996242627e-30 3.155443620841420423e-30" />
<geometry>
<mesh filename="package:///61804-2rs.stl"/>
</geometry>
</collision>
<visual>
<origin xyz="5.8286708792820718372e-15 0 0" rpy="2.722414939770826494e-14 1.9911547907015339569e-29 -3.7470892997510093599e-30" />
<geometry>
<mesh filename="package:///foot_ball.stl"/>
</geometry>
<material name="foot_ball_material">
<color rgba="0.26274509803921569651 0.28235294117647058432 0.30196078431372547213 1.0"/>
</material>
</visual>
<collision>
<origin xyz="5.8286708792820718372e-15 0 0" rpy="2.722414939770826494e-14 1.9911547907015339569e-29 -3.7470892997510093599e-30" />
<geometry>
<mesh filename="package:///foot_ball.stl"/>
</geometry>
</collision>
<visual>
<origin xyz="0 0 0.0059999999999999220623" rpy="1.5707963267948961139 -8.0213613529163596808e-14 1.0255191767872332309e-29" />
<geometry>
<mesh filename="package:///61804-2rs.stl"/>
</geometry>
<material name="61804-2rs_material">
<color rgba="0.61568627450980395466 0.81176470588235294379 0.92941176470588238168 1.0"/>
</material>
</visual>
<collision>
<origin xyz="0 0 0.0059999999999999220623" rpy="1.5707963267948961139 -8.0213613529163596808e-14 1.0255191767872332309e-29" />
<geometry>
<mesh filename="package:///61804-2rs.stl"/>
</geometry>
</collision>
<inertial>
<origin xyz="0.092866734428134811719 3.4061659201305072397e-09 -1.3731468342629295723e-09" rpy="0 0 0"/>
<mass value="0.13200000000000000622" />
<inertia ixx="1.7231392269124444922e-05" ixy="2.7776605628438480977e-11"  ixz="-1.1254075337182385848e-11" iyy="0.0009778131595366210127" iyz="-2.3904249366055512762e-11" izz="0.00098262259218384693377" />
</inertial>
</link>

<link name="HL_foot">
<inertial>
<origin xyz="0 0 0" rpy="0 0 0" />
<mass value="1e-9" />
<inertia ixx="0" ixy="0" ixz="0" iyy="0" iyz="0" izz="0" />
</inertial>
</link>
<joint name="HL_foot_frame" type="fixed">
<origin xyz="0.21732050807564629036 -2.7311486405778850894e-14 0" rpy="-1.57079632679489678 -2.7224149397708416402e-14 1.5707963267948661379" />
<parent link="lowerleg_sasm_3" />
<child link="HL_foot" />
<axis xyz="0 0 0"/>
</joint>

<joint name="HL2" type="revolute">
<origin xyz="0.21300000000000055 7.2719608112947753398e-15 -0.06849999999999886735" rpy="2.2204460491921242353e-16 -2.5540850755104416721e-14 6.4385996534357178978e-14" />
<parent link="upperleg_sasm_3" />
<child link="lowerleg_sasm_3" />
<axis xyz="0 0 1"/>
<limit effort="9" velocity="20" lower="-2.356194490192344837" upper="2.356194490192344837"/>
<joint_properties friction="0.0"/>
</joint>

<joint name="HL1" type="revolute">
<origin xyz="-3.0418668761338497323e-17 0.015999999999999986455 -0.05999999999999999778" rpy="1.570796326794896558 2.2747394953037020346e-15 3.2209162361520329144e-15" />
<parent link="helbow_sasm_3" />
<child link="upperleg_sasm_3" />
<axis xyz="0 0 1"/>
<limit effort="9" velocity="20" lower="-1.570796326794896558" upper="1.570796326794896558"/>
<joint_properties friction="0.0"/>
</joint>

<joint name="HL0" type="revolute">
<origin xyz="-0.16099999999999917155 0.060000000000000011657 -1.9408453586391257677e-16" rpy="-4.6713694273552509586e-30 1.570796326794896558 0" />
<parent link="body_sasm" />
<child link="helbow_sasm_3" />
<axis xyz="0 0 1"/>
<limit effort="9" velocity="20" lower="-0.785398163397448279" upper="0.785398163397448279"/>
<joint_properties friction="0.0"/>
</joint>

<link name="helbow_sasm_4">
<visual>
<origin xyz="-3.1225022567582527699e-17 -0.017000000000000001221 -0.05999999999999999778" rpy="1.570796326794896558 -0 0" />
<geometry>
<mesh filename="package:///angle_motor_connect.stl"/>
</geometry>
<material name="angle_motor_connect_material">
<color rgba="1 0 0 1.0"/>
</material>
</visual>
<collision>
<origin xyz="-3.1225022567582527699e-17 -0.017000000000000001221 -0.05999999999999999778" rpy="1.570796326794896558 -0 0" />
<geometry>
<mesh filename="package:///angle_motor_connect.stl"/>
</geometry>
</collision>
<visual>
<origin xyz="-3.1225022567582527699e-17 -0.017000000000000001221 -0.05999999999999999778" rpy="1.570796326794896558 0.3141592653589793116 3.1415926535897922278" />
<geometry>
<mesh filename="package:///rmdx8v3.stl"/>
</geometry>
<material name="rmdx8v3_material">
<color rgba="0.26274509803921569651 0.28235294117647058432 0.30196078431372547213 1.0"/>
</material>
</visual>
<collision>
<origin xyz="-3.1225022567582527699e-17 -0.017000000000000001221 -0.05999999999999999778" rpy="1.570796326794896558 0.3141592653589793116 3.1415926535897922278" />
<geometry>
<mesh filename="package:///rmdx8v3.stl"/>
</geometry>
</collision>
<inertial>
<origin xyz="5.9444804833178132404e-05 -0.0057855661598585012353 -0.054844450125644705896" rpy="0 0 0"/>
<mass value="0.76499999999999979128" />
<inertia ixx="0.00070529619085715842403" ixy="8.1991517066800189443e-07"  ixz="-1.1586194990787606344e-06" iyy="0.0010092480556627698822" iyz="9.9300977410701878745e-06" izz="0.00061029448812635514032" />
</inertial>
</link>

<link name="upperleg_sasm_4">
<visual>
<origin xyz="7.629021350754563618e-18 -2.7755575615628913511e-17 0.079250000000000334066" rpy="-1.570796326794896558 2.6499421621830933368e-30 -1.570796326794896558" />
<geometry>
<mesh filename="package:///61804-2rs.stl"/>
</geometry>
<material name="61804-2rs_material">
<color rgba="0.61568627450980395466 0.81176470588235294379 0.92941176470588238168 1.0"/>
</material>
</visual>
<collision>
<origin xyz="7.629021350754563618e-18 -2.7755575615628913511e-17 0.079250000000000334066" rpy="-1.570796326794896558 2.6499421621830933368e-30 -1.570796326794896558" />
<geometry>
<mesh filename="package:///61804-2rs.stl"/>
</geometry>
</collision>
<visual>
<origin xyz="1.3877787807816034477e-17 -2.7755575615628913511e-17 0.023000000000000020428" rpy="-2.2204460492474472971e-16 8.3815096766793541436e-30 -1.570796326794896558" />
<geometry>
<mesh filename="package:///rmdx8v3.stl"/>
</geometry>
<material name="rmdx8v3_material">
<color rgba="0.26274509803921569651 0.28235294117647058432 0.30196078431372547213 1.0"/>
</material>
</visual>
<collision>
<origin xyz="1.3877787807816034477e-17 -2.7755575615628913511e-17 0.023000000000000020428" rpy="-2.2204460492474472971e-16 8.3815096766793541436e-30 -1.570796326794896558" />
<geometry>
<mesh filename="package:///rmdx8v3.stl"/>
</geometry>
</collision>
<visual>
<origin xyz="2.2335275568130866206e-17 -2.7755575615628913511e-17 0.053500000000000005884" rpy="-1.1102230246304645882e-16 1.1102230246208832562e-16 2.0912209559343255345e-28" />
<geometry>
<mesh filename="package:///upperleg_main.stl"/>
</geometry>
<material name="upperleg_main_material">
<color rgba="1 0 0 1.0"/>
</material>
</visual>
<collision>
<origin xyz="2.2335275568130866206e-17 -2.7755575615628913511e-17 0.053500000000000005884" rpy="-1.1102230246304645882e-16 1.1102230246208832562e-16 2.0912209559343255345e-28" />
<geometry>
<mesh filename="package:///upperleg_main.stl"/>
</geometry>
</collision>
<visual>
<origin xyz="8.4574877603164094509e-18 -2.7755575615628913511e-17 0.053500000000000005884" rpy="-1.1102230246272406123e-16 1.110223024626815367e-16 -3.610542407486705846e-27" />
<geometry>
<mesh filename="package:///upperleg_cover.stl"/>
</geometry>
<material name="upperleg_cover_material">
<color rgba="1 0 0 1.0"/>
</material>
</visual>
<collision>
<origin xyz="8.4574877603164094509e-18 -2.7755575615628913511e-17 0.053500000000000005884" rpy="-1.1102230246272406123e-16 1.110223024626815367e-16 -3.610542407486705846e-27" />
<geometry>
<mesh filename="package:///upperleg_cover.stl"/>
</geometry>
</collision>
<visual>
<origin xyz="0 0 0.02300000000000000655" rpy="-1.570796326794896558 3.6620779973816428862e-30 1.479114197289388377e-31" />
<geometry>
<mesh filename="package:///inline_connect.stl"/>
</geometry>
<material name="inline_connect_material">
<color rgba="1 0 0 1.0"/>
</material>
</visual>
<collision>
<origin xyz="0 0 0.02300000000000000655" rpy="-1.570796326794896558 3.6620779973816428862e-30 1.479114197289388377e-31" />
<geometry>
<mesh filename="package:///inline_connect.stl"/>
</geometry>
</collision>
<visual>
<origin xyz="1.6430687626724614809e-18 -2.7755575615628913511e-17 0.056000000000000008105" rpy="-1.6535384173010603369e-14 1.5210055437364344837e-14 -1.570796326794896558" />
<geometry>
<mesh filename="package:///motor_pulley.stl"/>
</geometry>
<material name="motor_pulley_material">
<color rgba="1 0 0 1.0"/>
</material>
</visual>
<collision>
<origin xyz="1.6430687626724614809e-18 -2.7755575615628913511e-17 0.056000000000000008105" rpy="-1.6535384173010603369e-14 1.5210055437364344837e-14 -1.570796326794896558" />
<geometry>
<mesh filename="package:///motor_pulley.stl"/>
</geometry>
</collision>
<inertial>
<origin xyz="0.015354642915121934771 1.5253104182475208402e-07 0.040813023259634394202" rpy="0 0 0"/>
<mass value="0.89199999999999990408" />
<inertia ixx="0.00078712622936624667032" ixy="-2.0249252559590532338e-08"  ixz="-0.00040224017032634840074" iyy="0.0026932453248710609695" iyz="-3.6830453737564251339e-09" izz="0.0028289986488748415476" />
</inertial>
</link>

<link name="lowerleg_sasm_4">
<visual>
<origin xyz="0 0 0.0060000000000000330846" rpy="1.570796326794896558 1.1102230246494793408e-16 -1.6042472583800794153e-27" />
<geometry>
<mesh filename="package:///61804-2rs.stl"/>
</geometry>
<material name="61804-2rs_material">
<color rgba="0.61568627450980395466 0.81176470588235294379 0.92941176470588238168 1.0"/>
</material>
</visual>
<collision>
<origin xyz="0 0 0.0060000000000000330846" rpy="1.570796326794896558 1.1102230246494793408e-16 -1.6042472583800794153e-27" />
<geometry>
<mesh filename="package:///61804-2rs.stl"/>
</geometry>
</collision>
<visual>
<origin xyz="-5.5511151231257827021e-17 0 5.5511151231257827021e-17" rpy="3.141592653589793116 2.2204460492529631605e-16 -6.310887241768093042e-30" />
<geometry>
<mesh filename="package:///foot_ball.stl"/>
</geometry>
<material name="foot_ball_material">
<color rgba="0.26274509803921569651 0.28235294117647058432 0.30196078431372547213 1.0"/>
</material>
</visual>
<collision>
<origin xyz="-5.5511151231257827021e-17 0 5.5511151231257827021e-17" rpy="3.141592653589793116 2.2204460492529631605e-16 -6.310887241768093042e-30" />
<geometry>
<mesh filename="package:///foot_ball.stl"/>
</geometry>
</collision>
<visual>
<origin xyz="-2.7755575615628913511e-17 0 0" rpy="3.141592653589793116 2.7081386121130422452e-29 6.9518367272601623313e-30" />
<geometry>
<mesh filename="package:///lower_leg.stl"/>
</geometry>
<material name="lower_leg_material">
<color rgba="1 0 0 1.0"/>
</material>
</visual>
<collision>
<origin xyz="-2.7755575615628913511e-17 0 0" rpy="3.141592653589793116 2.7081386121130422452e-29 6.9518367272601623313e-30" />
<geometry>
<mesh filename="package:///lower_leg.stl"/>
</geometry>
</collision>
<visual>
<origin xyz="-2.7755575615628913511e-17 0 -0.0060000000000000053291" rpy="-1.57079632679489678 1.6297448791652292256e-29 7.5927862127522330219e-30" />
<geometry>
<mesh filename="package:///61804-2rs.stl"/>
</geometry>
<material name="61804-2rs_material">
<color rgba="0.61568627450980395466 0.81176470588235294379 0.92941176470588238168 1.0"/>
</material>
</visual>
<collision>
<origin xyz="-2.7755575615628913511e-17 0 -0.0060000000000000053291" rpy="-1.57079632679489678 1.6297448791652292256e-29 7.5927862127522330219e-30" />
<geometry>
<mesh filename="package:///61804-2rs.stl"/>
</geometry>
</collision>
<inertial>
<origin xyz="0.092866734428134811719 -3.4061659239153585728e-09 1.3731468278973485539e-09" rpy="0 0 0"/>
<mass value="0.13200000000000000622" />
<inertia ixx="1.7231392269124617717e-05" ixy="-2.7776605555558285542e-11"  ixz="1.1254075460849196147e-11" iyy="0.00097781315953662122954" iyz="-2.3904249472020121577e-11" izz="0.00098262259218384736745" />
</inertial>
</link>

<link name="HR_foot">
<inertial>
<origin xyz="0 0 0" rpy="0 0 0" />
<mass value="1e-9" />
<inertia ixx="0" ixy="0" ixz="0" iyy="0" iyz="0" izz="0" />
</inertial>
</link>
<joint name="HR_foot_frame" type="fixed">
<origin xyz="0.21732050807564637362 2.7283730830163221981e-14 0" rpy="-1.570796326794896558 2.2204460492510886297e-16 1.57079632679489678" />
<parent link="lowerleg_sasm_4" />
<child link="HR_foot" />
<axis xyz="0 0 0"/>
</joint>

<joint name="HR2" type="revolute">
<origin xyz="0.21300000000000002265 -6.467049118441536848e-15 0.068499999999999963696" rpy="1.1102230246387924942e-16 6.1232339957382020092e-17 -4.4630965589931286614e-14" />
<parent link="upperleg_sasm_4" />
<child link="lowerleg_sasm_4" />
<axis xyz="0 0 1"/>
<limit effort="9" velocity="20" lower="-2.356194490192344837" upper="2.356194490192344837"/>
<joint_properties friction="0.0"/>
</joint>

<joint name="HR1" type="revolute">
<origin xyz="-3.6033927686494999687e-17 0.016000000000000305644 -0.05999999999999999778" rpy="1.570796326794896558 7.3274719625260410554e-15 -3.141592653589793116" />
<parent link="helbow_sasm_4" />
<child link="upperleg_sasm_4" />
<axis xyz="0 0 1"/>
<limit effort="9" velocity="20" lower="-1.570796326794896558" upper="1.570796326794896558"/>
<joint_properties friction="0.0"/>
</joint>

<joint name="HR0" type="revolute">
<origin xyz="-0.16099999999999917155 -0.059999999999999983902 -1.9781398741257412101e-16" rpy="-3.141592653589793116 -1.5707963267947993025 0" />
<parent link="body_sasm" />
<child link="helbow_sasm_4" />
<axis xyz="0 0 1"/>
<limit effort="9" velocity="20" lower="-0.785398163397448279" upper="0.785398163397448279"/>
<joint_properties friction="0.0"/>
</joint>

<link name="arm1_sasm">
<visual>
<origin xyz="2.7755575615628913511e-17 -1.530808498934268238e-18 -0.034000000000000002442" rpy="-1.570796326794896558 3.246314345065296996e-17 -1.4964449862239514051e-31" />
<geometry>
<mesh filename="package:///5015.stl"/>
</geometry>
<material name="5015_material">
<color rgba="0.49803921568627451677 0.49803921568627451677 0.49803921568627451677 1.0"/>
</material>
</visual>
<collision>
<origin xyz="2.7755575615628913511e-17 -1.530808498934268238e-18 -0.034000000000000002442" rpy="-1.570796326794896558 3.246314345065296996e-17 -1.4964449862239514051e-31" />
<geometry>
<mesh filename="package:///5015.stl"/>
</geometry>
</collision>
<inertial>
<origin xyz="2.6627888228250157127e-17 4.872714790648413944e-19 -0.017000000000000001221" rpy="0 0 0"/>
<mass value="0.13500000000000000888" />
<inertia ixx="3.409875000000000281e-05" ixy="-3.2280664783648049001e-35"  ixz="-3.9054415336227386255e-21" iyy="3.409875000000000281e-05" iyz="-9.2071708132722372659e-36" izz="4.218750000000000901e-05" />
</inertial>
</link>

<link name="arm2_sasm">
<visual>
<origin xyz="-5.5511151231257827021e-17 2.7755575615628913511e-17 -0.034000000000000002442" rpy="-1.570796326794896558 1.1070902065631869695e-31 -0.785398163397448279" />
<geometry>
<mesh filename="package:///7015.stl"/>
</geometry>
<material name="7015_material">
<color rgba="0.49803921568627451677 0.49803921568627451677 0.49803921568627451677 1.0"/>
</material>
</visual>
<collision>
<origin xyz="-5.5511151231257827021e-17 2.7755575615628913511e-17 -0.034000000000000002442" rpy="-1.570796326794896558 1.1070902065631869695e-31 -0.785398163397448279" />
<geometry>
<mesh filename="package:///7015.stl"/>
</geometry>
</collision>
<visual>
<origin xyz="0.028284271247461689747 -0.028284271247461384435 2.2397479442724408186e-15" rpy="-1.570796326794896558 1.1070902065631869695e-31 -0.785398163397448279" />
<geometry>
<mesh filename="package:///link.stl"/>
</geometry>
<material name="link_material">
<color rgba="1 0 0 1.0"/>
</material>
</visual>
<collision>
<origin xyz="0.028284271247461689747 -0.028284271247461384435 2.2397479442724408186e-15" rpy="-1.570796326794896558 1.1070902065631869695e-31 -0.785398163397448279" />
<geometry>
<mesh filename="package:///link.stl"/>
</geometry>
</collision>
<visual>
<origin xyz="-1.6653345369377348106e-16 4.9960036108132044319e-16 0.015000000000002252851" rpy="-1.570796326794896558 1.1070902065631869695e-31 -0.785398163397448279" />
<geometry>
<mesh filename="package:///5015.stl"/>
</geometry>
<material name="5015_material">
<color rgba="0.49803921568627451677 0.49803921568627451677 0.49803921568627451677 1.0"/>
</material>
</visual>
<collision>
<origin xyz="-1.6653345369377348106e-16 4.9960036108132044319e-16 0.015000000000002252851" rpy="-1.570796326794896558 1.1070902065631869695e-31 -0.785398163397448279" />
<geometry>
<mesh filename="package:///5015.stl"/>
</geometry>
</collision>
<inertial>
<origin xyz="0.0036388221590199620187 -0.0036388221590198562005 -0.0022036505069926671727" rpy="0 0 0"/>
<mass value="0.56808517537055802649" />
<inertia ixx="0.00051493962243854499855" ixy="8.3530249615109691146e-05"  ixz="-2.0059007151600392974e-05" iyy="0.00051493962243854575749" iyz="2.0059007151598492232e-05" izz="0.00044450379764024981234" />
</inertial>
</link>

<link name="arm3_sasm">
<visual>
<origin xyz="0.039999999999999980016 2.7755575615628913511e-17 7.8886090522101180541e-31" rpy="1.570796326794896558 1.1070902065631256627e-31 0" />
<geometry>
<mesh filename="package:///link.stl"/>
</geometry>
<material name="link_material">
<color rgba="1 0 0 1.0"/>
</material>
</visual>
<collision>
<origin xyz="0.039999999999999980016 2.7755575615628913511e-17 7.8886090522101180541e-31" rpy="1.570796326794896558 1.1070902065631256627e-31 0" />
<geometry>
<mesh filename="package:///link.stl"/>
</geometry>
</collision>
<inertial>
<origin xyz="0.039999999999999986955 2.0725065917678788878e-17 -0.0074999999999999988551" rpy="0 0 0"/>
<mass value="0.073085175370557989294" />
<inertia ixx="8.7482462432131605847e-06" ixy="4.5554576774168977434e-37"  ixz="-3.738428140222723429e-36" iyy="7.3916526836105938257e-05" iyz="3.1198326063635762896e-36" izz="7.9924079002923183808e-05" />
</inertial>
</link>

<link name="end_effector_sasm">
<visual>
<origin xyz="0.014999999999999957812 1.3877787807814456755e-17 0.02999999999999999542" rpy="-1.570796326794896558 -4.0895337336256195199e-31 -5.7998163170288558874e-32" />
<geometry>
<mesh filename="package:///end_effector.stl"/>
</geometry>
<material name="end_effector_material">
<color rgba="0.2745098039215686514 0.2745098039215686514 0.2745098039215686514 1.0"/>
</material>
</visual>
<collision>
<origin xyz="0.014999999999999957812 1.3877787807814456755e-17 0.02999999999999999542" rpy="-1.570796326794896558 -4.0895337336256195199e-31 -5.7998163170288558874e-32" />
<geometry>
<mesh filename="package:///end_effector.stl"/>
</geometry>
</collision>
<visual>
<origin xyz="0.030000000000000026645 0.017988005261371856069 0.030000000000000005829" rpy="-1.570796326794896558 1.570796326794896558 0" />
<geometry>
<mesh filename="package:///t265.stl"/>
</geometry>
<material name="t265_material">
<color rgba="0.64705882352941179736 0.64705882352941179736 0.64705882352941179736 1.0"/>
</material>
</visual>
<collision>
<origin xyz="0.030000000000000026645 0.017988005261371856069 0.030000000000000005829" rpy="-1.570796326794896558 1.570796326794896558 0" />
<geometry>
<mesh filename="package:///t265.stl"/>
</geometry>
</collision>
<visual>
<origin xyz="-5.5511151231257827021e-17 1.3877787807814456755e-17 -0.025000000000000001388" rpy="-1.570796326794896558 -4.0895337336256195199e-31 -5.7998163170288558874e-32" />
<geometry>
<mesh filename="package:///2408.stl"/>
</geometry>
<material name="2408_material">
<color rgba="0.49803921568627451677 0.49803921568627451677 0.49803921568627451677 1.0"/>
</material>
</visual>
<collision>
<origin xyz="-5.5511151231257827021e-17 1.3877787807814456755e-17 -0.025000000000000001388" rpy="-1.570796326794896558 -4.0895337336256195199e-31 -5.7998163170288558874e-32" />
<geometry>
<mesh filename="package:///2408.stl"/>
</geometry>
</collision>
<inertial>
<origin xyz="0.019937599018672709505 0.0098116392334755622717 0.010681818181818181213" rpy="0 0 0"/>
<mass value="0.10999999999999998668" />
<inertia ixx="0.00012153320127288928213" ixy="-1.7931881802350382009e-05"  ixz="-4.2367397914679609397e-05" iyy="0.00014713632908573562666" iyz="-2.0849733371135534238e-05" izz="5.2640786405144492565e-05" />
</inertial>
</link>

<link name="gripper">
<visual>
<origin xyz="0.030000000000000026645 0.0029999999999999887867 -0.0050000000000000027062" rpy="1.570796326794896558 -1.601709792890827255e-31 0" />
<geometry>
<mesh filename="package:///gripper.stl"/>
</geometry>
<material name="gripper_material">
<color rgba="0.2745098039215686514 0.2745098039215686514 0.2745098039215686514 1.0"/>
</material>
</visual>
<collision>
<origin xyz="0.030000000000000026645 0.0029999999999999887867 -0.0050000000000000027062" rpy="1.570796326794896558 -1.601709792890827255e-31 0" />
<geometry>
<mesh filename="package:///gripper.stl"/>
</geometry>
</collision>
<inertial>
<origin xyz="0 0 0" rpy="0 0 0"/>
<mass value="0" />
<inertia ixx="0" ixy="0"  ixz="0" iyy="0" iyz="0" izz="0" />
</inertial>
</link>

<joint name="Gripper" type="revolute">
<origin xyz="0.034999999999999920064 -0.01199999999999999678 0.024999999999999994449" rpy="3.141592653589793116 -3.5728716727440510907e-16 1.3877787807815824936e-16" />
<parent link="end_effector_sasm" />
<child link="gripper" />
<axis xyz="0 0 1"/>
<limit effort="9" velocity="20" lower="0" upper="1.0471975511965976313"/>
<joint_properties friction="0.0"/>
</joint>

<joint name="OT" type="revolute">
<origin xyz="0.079999999999999960032 1.3877787807814456755e-17 -0.014999999999999999445" rpy="4.2353752921601641395e-31 1.1237174519383729543e-16 -1.3339013638364774884e-15" />
<parent link="arm3_sasm" />
<child link="end_effector_sasm" />
<axis xyz="0 0 1"/>
<limit effort="9" velocity="20" lower="-1.7453292519943295336" upper="1.7453292519943295336"/>
<joint_properties friction="0.0"/>
</joint>

<joint name="arm3" type="revolute">
<origin xyz="0.056568542494923657049 -0.056568542494923268471 2.2397479442724408186e-15" rpy="4.2353752921601877865e-31 8.995699258773243279e-31 -0.785398163397448279" />
<parent link="arm2_sasm" />
<child link="arm3_sasm" />
<axis xyz="0 0 1"/>
<limit effort="9" velocity="20" lower="-2.0943951023931952626" upper="2.0943951023931952626"/>
<joint_properties friction="0.0"/>
</joint>

<joint name="arm2" type="revolute">
<origin xyz="-2.7755575615628913511e-17 -3.3378680965872617913e-18 -0.068999999999999978018" rpy="-1.5707963267949001107 1.5707963267948954478 0" />
<parent link="arm1_sasm" />
<child link="arm2_sasm" />
<axis xyz="0 0 1"/>
<limit effort="9" velocity="20" lower="-0.785398163397448279" upper="2.356194490192344837"/>
<joint_properties friction="0.0"/>
</joint>

<joint name="arm1" type="revolute">
<origin xyz="0.20800000000000129496 -8.6389229103645397593e-16 0.050000000000000210942" rpy="-3.1415926535897895633 0.7853981633974522758 1.0958990010577604167e-14" />
<parent link="body_sasm" />
<child link="arm1_sasm" />
<axis xyz="0 0 1"/>
<limit effort="9" velocity="20" lower="-1.570796326794896558" upper="1.570796326794896558"/>
<joint_properties friction="0.0"/>
</joint>


</robot>
